Workbook

Sheet Data Flow Diagram

Sheet User Onboarding Tracker
A1: User Name | B1: Application | C1: LOB | D1: Region | E1: Required Role | F1: Access Status | G1: Date Requested | H1: Date Granted | I1: Notes / Blockers
A2: Alice Johnson | B2: SAP CPQ | C2: Onity | E2: Quotations Admin | F2: Granted | G2: 45901 | H2: 45903 | I2: –
A3: Alice Johnson | B3: CRM - SFDC | C3: Lenel S2 | D3: NA | E3: Sales Ops User | F3: Pending | G3: 45901 | H3: – | I3: Approval received; awaiting IT action
A4: Alice Johnson | B4: Sub Billing - Zuora | C4: Onity | D4: EMEA | E4: Billing Read-Only | F4: Granted | G4: 45901 | H4: 45902 | I4: –
A5: Alice Johnson | B5: LMS | E5: Learner | F5: Granted | G5: 45901 | H5: 45901 | I5: Auto-provisioned via HR system
A6: Bob Martinez | B6: SAP CPQ | E6: Sales Rep | F6: Pending | G6: 45905 | H6: – | I6: Missing manager approval
A7: Bob Martinez | B7: CRM- SFDC | E7: Sales Rep | F7: Pending | G7: 45905 | H7: – | I7: –
A8: Bob Martinez | B8: Sub Billing - Zuora | E8: – (N/A) | F8: N/A | G8: – | H8: – | I8: Not required for role
A9: Bob Martinez | B9: LMS | E9: Learner | F9: Granted
B10: Contact Centre
B11: AMS EAM - SFDC
B12: FSL - SFDC
B13: EDW
B14: CORA PPM

Sheet CCEX (Critical Data Elements)
A1: S.No | B1: Key Data Objects | C1: Source | D1: Destination | E1: Master Data / Transactional Data | F1: Architect Focal (Setup) | G1: Comments | H1: Critical Data Elements (To be loaded into Target System
A2: 1 | B2: Contacts | C2: GDM SFDC | D2: Contact Center | E2: Master Data | F2: Divya HV / Nagendra | G2: Phone | H2: Email
A3: 2 | B3: Material | C3: ERP | D3: CPQ | E3: Master Data | F3: Ashutosh Mishra | H3: SKU | I3: Product System ID | J3: Part Number | K3: Description | L3: Product Type | M3: Category | N3: Pricing Mechanism | O3: Description | P3: Product Catalogue | Q3: Product Hierarchy | R3: Catalogue Hierarchy | S3: Labor Cost | T3: Material Cost | U3: Sales Text | V3: Inclusion Exclusion List
A4: 3 | B4: Price | C4: ERP | D4: CPQ | E4: Master Data | F4: Ashutosh Mishra | H4: Involved_Parties | I4: Transaction_Type | J4: Sales_Org | K4: Buying_Method | L4: Product_SystemId | M4: Division | N4: Plant | O4: Price_Group | P4: Material_Price_Group
A5: 4 | B5: Region Mapping (CT_OGC_REGION_MAPPING) | C5: Business/ Manual | D5: CPQ | E5: Master Data | F5: Ashutosh Mishra | H5: SOR | I5: SALES_OFFICE | J5: ADR_LN1 | K5: ADR_LN2 | L5: ADR_LN3 | M5: ADR_LN4 | N5: ADR_LN5 | O5: PURCHASE | P5: SUSP | Q5: TRAINING
A6: 5 | B6: Contract (CT_AS_CONTRACT_ZA_ZL) | C6: Business/ Manual | D6: CPQ | E6: Master Data | F6: Ashutosh Mishra | H6: Country | I6: SalesOrg | J6: SKU | K6: ZA_Custcare_Advocate | L6: ZL_FSL
A7: 6 | B7: Accounts (Buying) | C7: ERP | D7: E-Commerce | E7: Master Data | F7: Sonam Kumari | H7: Ship-To ID | I7: Bill-To ID | J7: Sales Org | K7: Partner
A8: 7 | B8: Price | C8: ERP | D8: E-Commerce | E8: Master Data | F8: Sonam Kumari | H8: List Price | I8: Sales Org | J8: Currency | K8: UOM | L8: Valid From | M8: Valid To | N8: Price Territory
A9: 8 | B9: Credit Card MID | C9: NA | D9: E-Commerce | E9: Master Data | F9: Sonam Kumari | G9: Merchant id for credit card | H9: CompanyCode | I9: DocummentCurrency | J9: PaymentCardType | K9: accountNumber | L9: sapMID | M9: routingMID
A10: 9 | B10: Material/Product | C10: ERP / EPIM | D10: E-Commerce | E10: Master Data | F10: Sonam Kumari | H10: SKU ID | I10: Channel Status | J10: Category | K10: Item Plant | L10: Images | M10: Media / Documents | N10: Product Reference | O10: Classification | P10: UOM | Q10: Product Availability
A11: 10 | B11: Material/Product | C11: ERP | D11: ELMS (Lenel APAC) | E11: Master Data | F11: Sreeram Girish | H11: Material Number | I11: Description | J11: Sales Organization | K11: Item Category Group | L11: Product Hierarchy
A12: 11 | B12: Price | C12: ERP | D12: ELMS (Lenel APAC) | E12: Master Data | F12: Sreeram Girish | H12: Currency | I12: Unit Price | J12: Net Unit Price
A13: 12 | B13: Contacts (Portal) | C13: GDM SFDC | D13: ELMS (Lenel APAC) | E13: Master Data | F13: Sreeram Girish | H13: SFDC Contact ID | I13: Training ID | J13: Email Address | K13: Account.Product_Line__c
A14: 13 | B14: Training | C14: GDM SFDC | D14: ELMS (Lenel APAC) | E14: Transactional Data | F14: Sreeram Girish | H14: Certification Level | I14: Expiry Date | J14: Version | K14: Type | L14: Certificate Number
A15: 14 | B15: Leads | C15: HubSpot | D15: GDM Marketo | E15: Transactional Data | F15: Rawat Devendra Singh | G15: This is fine. | H15: First Name | I15: Email Address | J15: Company Name | K15: Job Title | L15: Country | M15: State | N15: City | O15: Postal Code | P15: Region | Q15: Email opt-in(Yes or No) | R15: Division | S15: Brand
A16: 15 | B16: Accounts (Buying) | C16: Source SFDC | D16: GDM SFDC | E16: Master Data | F16: Yaswanth\Divya | H16: BillingCity | I16: BillingCountry | J16: BillingPostalCode | K16: BillingState | L16: BillingStreet | M16: Industry | N16: Key_Account__c | O16: Name | P16: Phone | Q16: Product_Line__c | R16: ShippingCity | S16: ShippingCountry | T16: ShippingPostalCode | U16: ShippingState | V16: ShippingStreet | W16: Type | X16: Website | Y16: Region__c | Z16: Sub_Region__c | AA16: Hotel Chain | AB16: Hotel Brand | AC16: Hirarchy Type | AQ16: GBE__c | AR16: Brand2__c | AS16: Brand__c | AT16: Account_Status__c | AU16: Sales_Region__c | AV16: SBU__c | AW16: SBX__c
A17: 16 | B17: Accounts (Non-Buying) | C17: Source SFDC | D17: GDM SFDC | E17: Master Data | F17: Yaswanth\Divya | H17: BillingCity | I17: BillingCountry | J17: BillingPostalCode | K17: BillingState | L17: BillingStreet | M17: Industry | N17: Key_Account__c | O17: Name | P17: Phone | Q17: Product_Line__c | R17: ShippingCity | S17: ShippingCountry | T17: ShippingPostalCode | U17: ShippingState | V17: ShippingStreet | W17: Type | X17: Website | Y17: Region__c | Z17: Sub_Region__c | AA17: Hotel Chain | AB17: Hotel Brand | AC17: Hirarchy Type | AQ17: GBE__c | AR17: Brand2__c | AS17: Brand__c | AT17: Account_Status__c | AU17: Sales_Region__c | AV17: SBU__c | AW17: SBX__c
A18: 17 | B18: Source systems | C18: Source SFDC | D18: GDM SFDC | E18: Master Data | F18: Yaswanth\Divya | H18: Account__c | I18: Company_Code__c | J18: Credit_Freeze__c | K18: Credit_Limit__c | L18: Customer_Classification__c | M18: Customer_Order_Block__c | N18: Customer_Price_Group__c | O18: Distribution_Channel__c | P18: Division2__c | Q18: Source_System_Company_Id__c | R18: GBE2__c | S18: Industry__c | T18: Payment_Terms__c | U18: Sales_Area__c | V18: Sales_Group__c | W18: Sales_Office__c | X18: Sales_Organization__c | Y18: Sales_Org_Dist_Chan_Sales_Office__c | Z18: SBU__c | AQ18: Type__c | AR18: Source_System_Account_Name__c | AS18: Vertical_Market_Description__c | AT18: Street__c | AU18: City__c | AV18: State_Province__c | AW18: Postal_Code__c | AX18: Country__c | AY18: Source__c | AZ18: Source_Id__c | BA18: Instance_Name__c | BB18: Customer_Group_1__c | BC18: Customer_Sales_Category_1__c | BD18: Vertical_Market_Code__c | BE18: Sales_Group__c | BF18: Customer_Classification__c | BG18: Industry__c
A19: 18 | B19: Contact | C19: Source SFDC | D19: GDM SFDC | E19: Master Data | F19: Yaswanth\Divya | H19: AccountId | I19: Phone | J19: Department | K19: HasOptedOutOfEmail | L19: Email | M19: Fax | N19: HomePhone | O19: Training ID | P19: LeadSource | Q19: Mailingstreet | R19: Mailingcity | S19: MailingState | T19: mailingcountry | U19: Mailingpostalcode | V19: MobilePhone | W19: Name | X19: Salutation | Y19: FirstName | Z19: Alternate Email | AQ19: LastName | AR19: Personal_E_mail__c | AS19: Certification Hold | AT19: Title | AU19: Brand2__c | AV19: Product_Line__c | AW19: Region__c | AX19: SBU__c | AY19: SBX__c | AZ19: Contact Role
A20: 19 | B20: Account Team | C20: Source SFDC | D20: GDM SFDC | E20: Master Data | F20: Yaswanth\Divya | H20: AccountId | I20: AccountAccessLevel | J20: CaseAccessLevel | K20: ContactAccessLevel | L20: OpportunityAccessLevel | M20: UserId | N20: TeamMemberRole | O20: GBE | P20: Division | Q20: Primary | R20: Title | S20: Active
A21: 20 | B21: Product | C21: Source SFDC | D21: GDM SFDC | E21: Master Data | F21: Yaswanth\Divya | H21: IsActive | I21: ProductCode | J21: Product Description | K21: Name | L21: Brand | M21: Product_Family__c | N21: Product_Hierarchy__c
A22: 21 | B22: Account contact relationship | C22: Source SFDC | D22: GDM SFDC | E22: Transactional Data | F22: Yaswanth\Divya | H22: Account Name | I22: Active | J22: Direct | K22: E-Comm Active | L22: Account Status | M22: GBE | N22: Division | O22: Billing State/Province | P22: Billing Country | Q22: Billing City | R22: ContactId | S22: Contact_Name_Email__c | T22: Contact_Titan_Portal_Status__c | U22: E_Comm_Active__c
A23: 22 | B23: Lead | C23: Source SFDC | D23: GDM SFDC | E23: Transactional Data | F23: Yaswanth\Divya | H23: First Name | I23: Description | J23: Industry | K23: Email Opt Out | L23: IsUnreadByOwner | M23: GBE | N23: Region | O23: Division | P23: Division Detail | Q23: Brand | R23: Sales Region | S23: Product Line
A24: 23 | B24: Opportunity | C24: Source SFDC | D24: GDM SFDC | E24: Transactional Data | F24: Yaswanth\Divya | H24: AccountId | I24: Amount | J24: CloseDate | K24: Demo Presented | L24: Description | M24: Product Line | N24: End User Company | O24: First Shipment Date | P24: Forecast Category | Q24: Customer Industry | R24: LeadSource | S24: Win/Loss Reason (Primary) | T24: Win/Loss Comments | U24: NextStep | V24: Opportunity Name | W24: Opportunity Owner | X24: PO_Number__c | Y24: StageName | Z24: AssetId | AQ24: Customer Type | AR24: BillToSS | AS24: End User Company | AT24: Opportunity Type | AU24: Opportunity Sub Type | AV24: Go % | AW24: Win % | AX24: Probability (%) | AY24: Recommended Forecast Status | AZ24: Sold To Summary | BA24: Ship To Summary | BB24: Customer Type | BC24: Opportunity Vertical | BD24: Construction Type | BE24: Specification | BF24: GBE | BG24: Region | BH24: Division | BI24: Brand | BJ24: Product Line
A25: 24 | B25: Opportunity team | C25: Source SFDC | D25: GDM SFDC | E25: Transactional Data | F25: Yaswanth\Divya | H25: OpportunityId | I25: OpportunityAccessLevel | J25: TeamMemberRole | K25: UserId
A26: 25 | B26: Contract | C26: Source SFDC | D26: GDM SFDC | E26: Transactional Data | F26: Yaswanth\Divya | H26: Account Name | I26: Activated By | J26: Activated Date | K26: Contract Number | L26: Contract Owner | M26: Contract Name | N26: Contract Record Type | O26: Contract Start Date | P26: Created By | Q26: Customer Signed By | R26: Customer Signed Date | S26: Total Contract Amount | T26: Description | U26: Contract End Date | V26: Government VAR | W26: Company Signed By | X26: Company Signed Date | Y26: Named Accounts | Z26: Special Terms | AQ26: Recordtype Name | AR26: SLX Id | AS26: Status | AT26: Territory Description | AU26: Total Quota Rollup | AV26: Agreement Type | AW26: Legacy ID | AX26: Legacy Source
A27: 26 | B27: Cases | C27: Source SFDC | D27: GDM SFDC | E27: Transactional Data | F27: Yaswanth\Divya | H27: Description | I27: Notes__c | J27: Topic__c | K27: Issues__c | L27: AccountId | M27: SubRegion__c | N27: Notes__c | O27: Approver_Comments__c | P27: Approval_Status__c | Q27: AssetId | R27: Assigned_Timestamp__c | S27: Black_Support__c | T27: BusinessHoursId | U27: ContactId | V27: Reason | W27: Case_Reason_Subtype__c | X27: Status | Y27: Internal_Status__c | Z27: Subject | AQ27: Close_Reason__c
A28: 27 | B28: Knowledge articles | C28: Source SFDC | D28: GDM SFDC | E28: Transactional Data | F28: Yaswanth\Divya | H28: Answer_Solution__c | I28: RecordTypeId | J28: Language | K28: Question_Problem__c | L28: Summary | M28: Title | N28: UrlName | O28: IsVisibleInApp | P28: IsVisibleInPkb | Q28: IsVisibleInCsp | R28: IsVisibleInPrm | S28: GBE__c | T28: Status__c | U28: Type__c | V28: VersionNumber
A29: 28 | B29: Account Configuration | C29: Source SFDC | D29: GDM SFDC | E29: Transactional Data | F29: Yaswanth\Divya | H29: Account__c | I29: Affiliation__c | J29: Chain_ID__c | K29: Chain_Scale__c | L29: Class_Onity__c | M29: Customer_Class__c | N29: Floors_Onity__c | O29: Inn_MARSHA_Code__c | P29: OnPortal_Backup_Computer_Name__c | Q29: OnPortal_Software_Version__c | R29: Open_Date__c | S29: Operation_Onity__c | T29: Rooms__c | U29: Year_Affiliated_Onity__c | V29: Corporate_Billing__c | W29: API_ID__c | X29: Third_Party_App__c | Y29: DirectKey_Live__c | Z29: DirectKey_SaaS_Agreement_Effective_Date__c | AA29: DirectKey_SaaS_Agreement_Effective_Date__c | AB29: DirectKey_SaaS_Agreement_End_Date__c | AC29: Fee_per_lock_per_year__c
A30: 29 | B30: Accounts (Buying & Non-Buying) | C30: GDM SFDC | D30: Portal | E30: Master Data | F30: Kaustav | H30: Account | I30: Account Address (address, Postal Code, Zip Code, Country, Region ) | J30: Relationship of Buying & Non Buying Account (Partner, Role, Type) | K30: Product Lines | L30: Brand | M30: ERP Account Type
A31: 30 | B31: Contact | C31: GDM SFDC | D31: Portal | E31: Master Data | F31: Kaustav | H31: Honeywell_ID | I31: WPHID | J31: PURID | K31: Titan Portal Status | L31: ACR-Ecomm flag (E_Comm_Active__c) | M31: Email | N31: acr_id | O31: Address
A32: 31 | B32: Contact (Portal) - WPHID | C32: GDM SFDC | D32: Portal | E32: Master Data | F32: Kaustav | H32: Email Address | I32: Portal Status | J32: Persona
A33: 32 | B33: Contact (Portal) - PURID | C33: GDM SFDC | D33: Portal | E33: Master Data | F33: Kaustav | H33: Portal User Name | I33: EmailAddress | J33: Honeywell ID
A34: 33 | B34: Material/Product | C34: EPIM | D34: Portal | E34: Master Data | F34: Sunny Pachnanda | H34: AEM Catalog Rollout | I34: Elastic Product | J34: Elastic SKU | K34: Target Market
A35: 34 | B35: Software Metadata | C35: Azure Blob | D35: Portal | E35: Master Data | F35: Sunny Pachnanda | H35: Software Name | I35: Software file type | J35: Software Target audience (Public / Private) | K35: Software Searchable (Yes/No) | L35: Software Visible (Yes/No) | M35: SKU | N35: Sku Description | O35: Product Family | P35: Product Category | Q35: Region (If Any) | R35: Software Description | S35: Brand | T35: File Size | U35: Version | V35: Pre-requsite | W35: FileName | X35: File Type | Y35: File Size | Z35: Country | AA35: Region
A36: 35 | B36: Var Agreements | C36: GDM SFDC | D36: Portal | E36: Transactional Data | F36: Sunny Pachnanda | H36: Agreement_Type__c | I36: Status | J36: EndDate | K36: AccountId
A37: 36 | B37: Cases | C37: GDM SFDC | D37: Portal | E37: Transactional Data | F37: Sunny Pachnanda | H37: Case Type | I37: Case origin | J37: Case Owner | K37: Case End User Account | L37: System ID | M37: Description | N37: Type | O37: Status | P37: Reason
A38: 37 | B38: Orders | C38: ERP | D38: Portal | E38: Transactional Data | F38: Sunny Pachnanda | H38: Invoice ID | I38: Order Id | J38: Order Number | K38: Sold To Number , Name & Address | L38: PO Number | M38: Order Type | N38: Total Amount | O38: Currency | P38: Ship To Number , Name & Address | Q38: Sales Org | R38: Division | S38: Dist. Channel | T38: Status | U38: Profit Center | V38: Part Number | W38: Bill To Number , Name & Address | X38: Credit Block | Y38: Order Tax and Net Value | Z38: Order Date | AA38: lineItemNumber | AB38: catalogNumber | AC38: conditionRate | AD38: line Item Net Price and Net Value | AE38: lineItemOrderStatus | AF38: Line Item Tax | AG38: estimatedDeliveryDate | AH38: shippingDate | AI38: Line item Currency | AJ38: Product Number & Description | AK38: Profit Center | AL38: quantity | AM38: unitOfMeasure | AN38: quantityDue | AO38: quantityShipped | AP38: Deliveries
A39: 38 | B39: Material/Product | C39: ERP | D39: Pros | E39: Master Data | F39: Vimal Kumar | H39: SKU | I39: Sales Org | J39: Plant
A40: 39 | B40: Price | C40: Business/ Manual | D40: Pros | E40: Master Data | F40: Vimal Kumar | H40: SKU | I40: MSRP - Not applicable | J40: List price | K40: Standard Discount | L40: Negotiated Disc Net Price - Not applicable | M40: Negotiated Discount % - Not applicable | N40: Promotional Discounts % - Not applicable | O40: Volume Discounts % - Not applicable | P40: Transfer Prices
...

Sheet CCEX Data Score Card - UAT
B1: System | C1: Data Object Type | D1: Data Object | E1: Region | F1: Business Focal | G1: Identify CDE | H1: Prep Data | I1: Load | J1: Validation | K1: Status % | L1: Progress | M1: ETA for Validation | N1: Expected Records (UAT) | O1: Loaded Records (UAT) | P1: % Loaded (UAT) | Q1: Missed Records (UAT) | R1: % Problem (UAT) | S1: Remarks / Comments during UAT
A2: 1 | B2: Salesforce | C2: Master Data | D2: Account (Buying) | E2: Onity NA | F2: Anne Kelly - CS Chris Taylor - TC | G2: TRUE | H2: TRUE | I2: TRUE | J2: TRUE | K2: =REPT("|||||||||||||||||||||||",COUNTIF(G2:J2,TRUE)) -> |||||||||||||||||||||||||||||||||||||||||||||||||||||||||||||||||||||||||||||||||||||||||||| | L2: =TEXT(COUNTIF(G2:J2,TRUE)/COLUMNS(G2:J2),"0%") -> 100% | M2: 45918 | N2: 19378 | O2: 19378 | P2: =IFERROR(O2/N2,0) -> 1 | Q2: =IFERROR(N2-O2,0) -> 0 | R2: =IFERROR(Q2/N2,0) -> 0
A3: 2 | B3: Salesforce | C3: Master Data | D3: Account (Non-Buying) | E3: Onity NA | G3: TRUE | H3: TRUE | I3: TRUE | J3: TRUE | K3: =REPT("|||||||||||||||||||||||",COUNTIF(G3:J3,TRUE)) -> |||||||||||||||||||||||||||||||||||||||||||||||||||||||||||||||||||||||||||||||||||||||||||| | L3: =TEXT(COUNTIF(G3:J3,TRUE)/COLUMNS(G3:J3),"0%") -> 100% | M3: 45918 | N3: 114057 | O3: 114057 | P3: =IFERROR(O3/N3,0) -> 1 | Q3: =IFERROR(N3-O3,0) -> 0 | R3: =IFERROR(Q3/N3,0) -> 0
A4: 3 | B4: Salesforce | C4: Master Data | D4: Contact | E4: Onity NA | G4: TRUE | H4: TRUE | I4: TRUE | J4: TRUE | K4: =REPT("|||||||||||||||||||||||",COUNTIF(G4:J4,TRUE)) -> |||||||||||||||||||||||||||||||||||||||||||||||||||||||||||||||||||||||||||||||||||||||||||| | L4: =TEXT(COUNTIF(G4:J4,TRUE)/COLUMNS(G4:J4),"0%") -> 100% | M4: 45918 | N4: 194312 | O4: 194312 | P4: =IFERROR(O4/N4,0) -> 1 | Q4: =IFERROR(N4-O4,0) -> 0 | R4: =IFERROR(Q4/N4,0) -> 0
A5: 4 | B5: Salesforce | C5: Master Data | D5: Product | E5: Onity NA | G5: TRUE | H5: TRUE | I5: TRUE | J5: TRUE | K5: =REPT("|||||||||||||||||||||||",COUNTIF(G5:J5,TRUE)) -> |||||||||||||||||||||||||||||||||||||||||||||||||||||||||||||||||||||||||||||||||||||||||||| | L5: =TEXT(COUNTIF(G5:J5,TRUE)/COLUMNS(G5:J5),"0%") -> 100% | M5: 45918 | N5: 13812 | O5: 13812 | P5: =IFERROR(O5/N5,0) -> 1 | Q5: =IFERROR(N5-O5,0) -> 0 | R5: =IFERROR(Q5/N5,0) -> 0
A6: 5 | B6: Salesforce | C6: Transactional Data | D6: Opportunity | E6: Onity NA | G6: TRUE | H6: TRUE | I6: TRUE | J6: TRUE | K6: =REPT("|||||||||||||||||||||||",COUNTIF(G6:J6,TRUE)) -> |||||||||||||||||||||||||||||||||||||||||||||||||||||||||||||||||||||||||||||||||||||||||||| | L6: =TEXT(COUNTIF(G6:J6,TRUE)/COLUMNS(G6:J6),"0%") -> 100% | M6: 45918 | N6: 11067 | O6: 11067 | P6: =IFERROR(O6/N6,0) -> 1 | Q6: =IFERROR(N6-O6,0) -> 0 | R6: =IFERROR(Q6/N6,0) -> 0
A7: 6 | B7: Salesforce | C7: Transactional Data | D7: Lead | E7: Onity NA | G7: TRUE | H7: TRUE | I7: TRUE | J7: TRUE | K7: =REPT("|||||||||||||||||||||||",COUNTIF(G7:J7,TRUE)) -> |||||||||||||||||||||||||||||||||||||||||||||||||||||||||||||||||||||||||||||||||||||||||||| | L7: =TEXT(COUNTIF(G7:J7,TRUE)/COLUMNS(G7:J7),"0%") -> 100% | M7: 45918 | N7: 352 | O7: 352 | P7: =IFERROR(O7/N7,0) -> 1 | Q7: =IFERROR(N7-O7,0) -> 0 | R7: =IFERROR(Q7/N7,0) -> 0
A8: 7 | B8: Salesforce | C8: Transactional Data | D8: Contract | E8: Onity NA | G8: TRUE | H8: TRUE | I8: TRUE | J8: TRUE | K8: =REPT("|||||||||||||||||||||||",COUNTIF(G8:J8,TRUE)) -> |||||||||||||||||||||||||||||||||||||||||||||||||||||||||||||||||||||||||||||||||||||||||||| | L8: =TEXT(COUNTIF(G8:J8,TRUE)/COLUMNS(G8:J8),"0%") -> 100% | M8: 45918 | N8: 5491 | O8: 5491 | P8: =IFERROR(O8/N8,0) -> 1 | Q8: =IFERROR(N8-O8,0) -> 0 | R8: =IFERROR(Q8/N8,0) -> 0
A9: 8 | B9: Salesforce | C9: Transactional Data | D9: Service Contract | E9: Onity NA | G9: TRUE | H9: TRUE | I9: TRUE | J9: TRUE | K9: =REPT("|||||||||||||||||||||||",COUNTIF(G9:J9,TRUE)) -> |||||||||||||||||||||||||||||||||||||||||||||||||||||||||||||||||||||||||||||||||||||||||||| | L9: =TEXT(COUNTIF(G9:J9,TRUE)/COLUMNS(G9:J9),"0%") -> 100% | M9: 45943 | N9: 803 | O9: 803 | P9: =IFERROR(O9/N9,0) -> 1 | Q9: 0 | R9: =IFERROR(Q9/N9,0) -> 0
A10: 9 | B10: Salesforce | C10: Transactional Data | D10: Case | E10: Onity NA | G10: TRUE | H10: TRUE | I10: TRUE | J10: TRUE | K10: =REPT("|||||||||||||||||||||||",COUNTIF(G10:J10,TRUE)) -> |||||||||||||||||||||||||||||||||||||||||||||||||||||||||||||||||||||||||||||||||||||||||||| | L10: =TEXT(COUNTIF(G10:J10,TRUE)/COLUMNS(G10:J10),"0%") -> 100% | M10: 45918 | N10: 102614 | O10: 102614 | P10: =IFERROR(O10/N10,0) -> 1 | Q10: =IFERROR(N10-O10,0) -> 0 | R10: =IFERROR(Q10/N10,0) -> 0
A11: 10 | B11: Salesforce | C11: Transactional Data | D11: Knowledge Articles | E11: Onity NA | G11: TRUE | H11: TRUE | I11: TRUE | J11: TRUE | K11: =REPT("|||||||||||||||||||||||",COUNTIF(G11:J11,TRUE)) -> |||||||||||||||||||||||||||||||||||||||||||||||||||||||||||||||||||||||||||||||||||||||||||| | L11: =TEXT(COUNTIF(G11:J11,TRUE)/COLUMNS(G11:J11),"0%") -> 100% | M11: 45939 | N11: 344 | O11: 344 | P11: =IFERROR(O11/N11,0) -> 1 | Q11: =IFERROR(N11-O11,0) -> 0 | R11: =IFERROR(Q11/N11,0) -> 0
A12: 11 | B12: Salesforce | C12: Master Data | D12: Account (Buying) | E12: Onity EMEA | F12: Piorno Abelardo Sonia Estrada | G12: TRUE | H12: TRUE | I12: TRUE | J12: TRUE | K12: =REPT("|||||||||||||||||||||||",COUNTIF(G12:J12,TRUE)) -> |||||||||||||||||||||||||||||||||||||||||||||||||||||||||||||||||||||||||||||||||||||||||||| | L12: =TEXT(COUNTIF(G12:J12,TRUE)/COLUMNS(G12:J12),"0%") -> 100% | M12: 45939 | N12: 19478 | O12: 19478 | P12: =IFERROR(O12/N12,0) -> 1 | Q12: =IFERROR(N12-O12,0) -> 0 | R12: =IFERROR(Q12/N12,0) -> 0
A13: 12 | B13: Salesforce | C13: Master Data | D13: Account (Non-Buying) | E13: Onity EMEA | G13: TRUE | H13: TRUE | I13: TRUE | J13: TRUE | K13: =REPT("|||||||||||||||||||||||",COUNTIF(G13:J13,TRUE)) -> |||||||||||||||||||||||||||||||||||||||||||||||||||||||||||||||||||||||||||||||||||||||||||| | L13: =TEXT(COUNTIF(G13:J13,TRUE)/COLUMNS(G13:J13),"0%") -> 100% | M13: 45939 | N13: 25438 | O13: 25438 | P13: =IFERROR(O13/N13,0) -> 1 | Q13: =IFERROR(N13-O13,0) -> 0 | R13: =IFERROR(Q13/N13,0) -> 0
A14: 13 | B14: Salesforce | C14: Master Data | D14: Contact | E14: Onity EMEA | G14: TRUE | H14: TRUE | I14: TRUE | J14: TRUE | K14: =REPT("|||||||||||||||||||||||",COUNTIF(G14:J14,TRUE)) -> |||||||||||||||||||||||||||||||||||||||||||||||||||||||||||||||||||||||||||||||||||||||||||| | L14: =TEXT(COUNTIF(G14:J14,TRUE)/COLUMNS(G14:J14),"0%") -> 100% | M14: 45939 | N14: 23800 | O14: 23800 | P14: =IFERROR(O14/N14,0) -> 1 | Q14: =IFERROR(N14-O14,0) -> 0 | R14: =IFERROR(Q14/N14,0) -> 0
A15: 14 | B15: Salesforce | C15: Master Data | D15: Product | E15: Onity EMEA | G15: TRUE | H15: TRUE | I15: TRUE | J15: TRUE | K15: =REPT("|||||||||||||||||||||||",COUNTIF(G15:J15,TRUE)) -> |||||||||||||||||||||||||||||||||||||||||||||||||||||||||||||||||||||||||||||||||||||||||||| | L15: =TEXT(COUNTIF(G15:J15,TRUE)/COLUMNS(G15:J15),"0%") -> 100% | M15: 45939 | N15: 13812 | O15: 13812 | P15: =IFERROR(O15/N15,0) -> 1 | Q15: =IFERROR(N15-O15,0) -> 0 | R15: =IFERROR(Q15/N15,0) -> 0
A16: 15 | B16: Salesforce | C16: Transactional Data | D16: Opportunity | E16: Onity EMEA | G16: TRUE | H16: TRUE | I16: TRUE | J16: TRUE | K16: =REPT("|||||||||||||||||||||||",COUNTIF(G16:J16,TRUE)) -> |||||||||||||||||||||||||||||||||||||||||||||||||||||||||||||||||||||||||||||||||||||||||||| | L16: =TEXT(COUNTIF(G16:J16,TRUE)/COLUMNS(G16:J16),"0%") -> 100% | M16: 45939 | N16: 31155 | O16: 31155 | P16: =IFERROR(O16/N16,0) -> 1 | Q16: =IFERROR(N16-O16,0) -> 0 | R16: =IFERROR(Q16/N16,0) -> 0
A17: 16 | B17: Salesforce | C17: Transactional Data | D17: Service Contract | E17: Onity EMEA | G17: TRUE | H17: TRUE | I17: TRUE | J17: TRUE | K17: =REPT("|||||||||||||||||||||||",COUNTIF(G17:J17,TRUE)) -> |||||||||||||||||||||||||||||||||||||||||||||||||||||||||||||||||||||||||||||||||||||||||||| | L17: =TEXT(COUNTIF(G17:J17,TRUE)/COLUMNS(G17:J17),"0%") -> 100% | M17: 45943 | N17: 289 | O17: 289 | P17: =IFERROR(O17/N17,0) -> 1 | Q17: 0 | R17: =IFERROR(Q17/N17,0) -> 0
A18: 17 | B18: Salesforce | C18: Transactional Data | D18: Case | E18: Onity EMEA | G18: TRUE | H18: TRUE | I18: TRUE | J18: TRUE | K18: =REPT("|||||||||||||||||||||||",COUNTIF(G18:J18,TRUE)) -> |||||||||||||||||||||||||||||||||||||||||||||||||||||||||||||||||||||||||||||||||||||||||||| | L18: =TEXT(COUNTIF(G18:J18,TRUE)/COLUMNS(G18:J18),"0%") -> 100% | M18: 45943 | N18: 1968 | O18: 1968 | P18: =IFERROR(O18/N18,0) -> 1 | Q18: =IFERROR(N18-O18,0) -> 0 | R18: =IFERROR(Q18/N18,0) -> 0
A19: 18 | B19: Salesforce | C19: Transactional Data | D19: Quote | E19: Onity EMEA | G19: TRUE | H19: TRUE | I19: TRUE | J19: TRUE | K19: =REPT("|||||||||||||||||||||||",COUNTIF(G19:J19,TRUE)) -> |||||||||||||||||||||||||||||||||||||||||||||||||||||||||||||||||||||||||||||||||||||||||||| | L19: =TEXT(COUNTIF(G19:J19,TRUE)/COLUMNS(G19:J19),"0%") -> 100% | M19: 45943 | N19: 8195 | O19: 8195 | P19: =IFERROR(O19/N19,0) -> 1 | Q19: =IFERROR(N19-O19,0) -> 0 | R19: =IFERROR(Q19/N19,0) -> 0
A20: 19 | B20: Salesforce | C20: Master Data | D20: Account (Buying) | E20: Onity APAC | F20: Chin Edmond- RoA Suriati Nur- GC, RoA David Carran- Ken Ong - ANZ James Eapen- Ind | G20: TRUE | H20: TRUE | I20: TRUE | J20: TRUE | K20: =REPT("|||||||||||||||||||||||",COUNTIF(G20:J20,TRUE)) -> |||||||||||||||||||||||||||||||||||||||||||||||||||||||||||||||||||||||||||||||||||||||||||| | L20: =TEXT(COUNTIF(G20:J20,TRUE)/COLUMNS(G20:J20),"0%") -> 100% | M20: 45939 | N20: 6267 | O20: 6267 | P20: =IFERROR(O20/N20,0) -> 1 | Q20: =IFERROR(N20-O20,0) -> 0 | R20: =IFERROR(Q20/N20,0) -> 0
A21: 20 | B21: Salesforce | C21: Master Data | D21: Contact | E21: Onity APAC | G21: TRUE | H21: TRUE | I21: TRUE | J21: TRUE | K21: =REPT("|||||||||||||||||||||||",COUNTIF(G21:J21,TRUE)) -> |||||||||||||||||||||||||||||||||||||||||||||||||||||||||||||||||||||||||||||||||||||||||||| | L21: =TEXT(COUNTIF(G21:J21,TRUE)/COLUMNS(G21:J21),"0%") -> 100% | M21: 45939 | N21: 25 | O21: 25 | P21: =IFERROR(O21/N21,0) -> 1 | Q21: =IFERROR(N21-O21,0) -> 0 | R21: =IFERROR(Q21/N21,0) -> 0
A22: 21 | B22: Salesforce | C22: Master Data | D22: Product | E22: Onity APAC | G22: TRUE | H22: TRUE | I22: TRUE | J22: TRUE | K22: =REPT("|||||||||||||||||||||||",COUNTIF(G22:J22,TRUE)) -> |||||||||||||||||||||||||||||||||||||||||||||||||||||||||||||||||||||||||||||||||||||||||||| | L22: =TEXT(COUNTIF(G22:J22,TRUE)/COLUMNS(G22:J22),"0%") -> 100% | M22: 45939 | N22: 4149 | O22: 4149 | P22: =IFERROR(O22/N22,0) -> 1 | Q22: =IFERROR(N22-O22,0) -> 0 | R22: =IFERROR(Q22/N22,0) -> 0
A23: 22 | B23: Salesforce | C23: Master Data | D23: Account (Buying) | E23: Lenel APAC | F23: Suriati Nur- RoA, GC Ken Ong - ANZ James Eapen- Ind | G23: TRUE | H23: TRUE | I23: TRUE | J23: TRUE | K23: =REPT("|||||||||||||||||||||||",COUNTIF(G23:J23,TRUE)) -> |||||||||||||||||||||||||||||||||||||||||||||||||||||||||||||||||||||||||||||||||||||||||||| | L23: =TEXT(COUNTIF(G23:J23,TRUE)/COLUMNS(G23:J23),"0%") -> 100% | M23: 45939 | N23: 300 | O23: 300 | P23: =IFERROR(O23/N23,0) -> 1 | Q23: =IFERROR(N23-O23,0) -> 0 | R23: =IFERROR(Q23/N23,0) -> 0
A24: 23 | B24: Salesforce | C24: Master Data | D24: Account (Non-Buying) | E24: Lenel APAC | G24: TRUE | H24: TRUE | I24: TRUE | J24: TRUE | K24: =REPT("|||||||||||||||||||||||",COUNTIF(G24:J24,TRUE)) -> |||||||||||||||||||||||||||||||||||||||||||||||||||||||||||||||||||||||||||||||||||||||||||| | L24: =TEXT(COUNTIF(G24:J24,TRUE)/COLUMNS(G24:J24),"0%") -> 100% | M24: 45939 | N24: 9832 | O24: 9832 | P24: =IFERROR(O24/N24,0) -> 1 | Q24: =IFERROR(N24-O24,0) -> 0 | R24: =IFERROR(Q24/N24,0) -> 0
A25: 24 | B25: Salesforce | C25: Master Data | D25: Contact | E25: Lenel APAC | G25: TRUE | H25: TRUE | I25: TRUE | J25: TRUE | K25: =REPT("|||||||||||||||||||||||",COUNTIF(G25:J25,TRUE)) -> |||||||||||||||||||||||||||||||||||||||||||||||||||||||||||||||||||||||||||||||||||||||||||| | L25: =TEXT(COUNTIF(G25:J25,TRUE)/COLUMNS(G25:J25),"0%") -> 100% | M25: 45939 | N25: 4936 | O25: 4936 | P25: =IFERROR(O25/N25,0) -> 1 | Q25: =IFERROR(N25-O25,0) -> 0 | R25: =IFERROR(Q25/N25,0) -> 0
A26: 25 | B26: Salesforce | C26: Master Data | D26: Product | E26: Lenel APAC | G26: TRUE | H26: TRUE | I26: TRUE | J26: TRUE | K26: =REPT("|||||||||||||||||||||||",COUNTIF(G26:J26,TRUE)) -> |||||||||||||||||||||||||||||||||||||||||||||||||||||||||||||||||||||||||||||||||||||||||||| | L26: =TEXT(COUNTIF(G26:J26,TRUE)/COLUMNS(G26:J26),"0%") -> 100% | M26: 45939 | N26: 2275 | O26: 2275 | P26: =IFERROR(O26/N26,0) -> 1 | Q26: =IFERROR(N26-O26,0) -> 0 | R26: =IFERROR(Q26/N26,0) -> 0
A27: 26 | B27: Salesforce | C27: Transactional Data | D27: Opportunity | E27: Lenel APAC | G27: TRUE | H27: TRUE | I27: TRUE | J27: TRUE | K27: =REPT("|||||||||||||||||||||||",COUNTIF(G27:J27,TRUE)) -> |||||||||||||||||||||||||||||||||||||||||||||||||||||||||||||||||||||||||||||||||||||||||||| | L27: =TEXT(COUNTIF(G27:J27,TRUE)/COLUMNS(G27:J27),"0%") -> 100% | M27: 45940 | N27: 1168 | O27: 1168 | P27: =IFERROR(O27/N27,0) -> 1 | Q27: =IFERROR(N27-O27,0) -> 0 | R27: =IFERROR(Q27/N27,0) -> 0
A28: 27 | B28: Salesforce | C28: Transactional Data | D28: Service Contract | E28: Lenel APAC | G28: TRUE | H28: TRUE | I28: TRUE | J28: TRUE | K28: =REPT("|||||||||||||||||||||||",COUNTIF(G28:J28,TRUE)) -> |||||||||||||||||||||||||||||||||||||||||||||||||||||||||||||||||||||||||||||||||||||||||||| | L28: =TEXT(COUNTIF(G28:J28,TRUE)/COLUMNS(G28:J28),"0%") -> 100% | M28: 45940 | N28: 34 | O28: 34 | P28: =IFERROR(O28/N28,0) -> 1 | Q28: =IFERROR(N28-O28,0) -> 0 | R28: =IFERROR(Q28/N28,0) -> 0
A29: 28 | B29: SMS SFDC | C29: Transactional Data | D29: Service Contract | E29: Onity NA | F29: Kathleen | G29: TRUE | H29: TRUE | I29: TRUE | J29: TRUE | K29: =REPT("|||||||||||||||||||||||",COUNTIF(G29:J29,TRUE)) -> |||||||||||||||||||||||||||||||||||||||||||||||||||||||||||||||||||||||||||||||||||||||||||| | L29: =TEXT(COUNTIF(G29:J29,TRUE)/COLUMNS(G29:J29),"0%") -> 100% | M29: 45945 | N29: 2488 | O29: 2488 | P29: =IFERROR(O29/N29,0) -> 1 | Q29: 0 | R29: =IFERROR(Q29/N29,0) -> 0
A30: 29 | B30: SMS SFDC | C30: Master Data | D30: SMS - Subcontractors and internal | E30: Onity NA | G30: TRUE | H30: TRUE | I30: TRUE | J30: TRUE | K30: =REPT("|||||||||||||||||||||||",COUNTIF(G30:J30,TRUE)) -> |||||||||||||||||||||||||||||||||||||||||||||||||||||||||||||||||||||||||||||||||||||||||||| | L30: =TEXT(COUNTIF(G30:J30,TRUE)/COLUMNS(G30:J30),"0%") -> 100% | M30: 45939 | N30: 44 | O30: 44 | P30: =IFERROR(O30/N30,0) -> 1 | Q30: 0 | R30: =IFERROR(Q30/N30,0) -> 0
A31: 30 | B31: SMS SFDC | C31: Master Data | D31: SMS - Work Type Setup | E31: Onity NA | G31: TRUE | H31: TRUE | I31: TRUE | J31: TRUE | K31: =REPT("|||||||||||||||||||||||",COUNTIF(G31:J31,TRUE)) -> |||||||||||||||||||||||||||||||||||||||||||||||||||||||||||||||||||||||||||||||||||||||||||| | L31: =TEXT(COUNTIF(G31:J31,TRUE)/COLUMNS(G31:J31),"0%") -> 100% | M31: 45945 | N31: 48 | O31: 48 | P31: =IFERROR(O31/N31,0) -> 1 | Q31: =IFERROR(N31-O31,0) -> 0 | R31: =IFERROR(Q31/N31,0) -> 0
A32: 31 | B32: SMS SFDC | C32: Master Data | D32: SMS - Service Territory | E32: Onity NA | G32: TRUE | H32: TRUE | I32: TRUE | J32: TRUE | K32: =REPT("|||||||||||||||||||||||",COUNTIF(G32:J32,TRUE)) -> |||||||||||||||||||||||||||||||||||||||||||||||||||||||||||||||||||||||||||||||||||||||||||| | L32: =TEXT(COUNTIF(G32:J32,TRUE)/COLUMNS(G32:J32),"0%") -> 100% | M32: 45939 | N32: 4 | O32: 4 | P32: =IFERROR(O32/N32,0) -> 1 | Q32: =IFERROR(N32-O32,0) -> 0 | R32: =IFERROR(Q32/N32,0) -> 0
A33: 32 | B33: SMS SFDC | C33: Master Data | D33: SMS - Profit Center | E33: Onity NA | G33: TRUE | H33: TRUE | I33: TRUE | J33: TRUE | K33: =REPT("|||||||||||||||||||||||",COUNTIF(G33:J33,TRUE)) -> |||||||||||||||||||||||||||||||||||||||||||||||||||||||||||||||||||||||||||||||||||||||||||| | L33: =TEXT(COUNTIF(G33:J33,TRUE)/COLUMNS(G33:J33),"0%") -> 100% | M33: 45939 | N33: 8 | O33: 8 | P33: =IFERROR(O33/N33,0) -> 1 | Q33: =IFERROR(N33-O33,0) -> 0 | R33: =IFERROR(Q33/N33,0) -> 0
A34: 33 | B34: SMS SFDC | C34: Master Data | D34: SMS - Service Resource Setup | E34: Onity NA | G34: TRUE | H34: TRUE | I34: TRUE | J34: TRUE | K34: =REPT("|||||||||||||||||||||||",COUNTIF(G34:J34,TRUE)) -> |||||||||||||||||||||||||||||||||||||||||||||||||||||||||||||||||||||||||||||||||||||||||||| | L34: =TEXT(COUNTIF(G34:J34,TRUE)/COLUMNS(G34:J34),"0%") -> 100% | M34: 45939 | N34: 122 | O34: 122 | P34: =IFERROR(O34/N34,0) -> 1 | Q34: 0 | R34: =IFERROR(Q34/N34,0) -> 0
A35: 34 | B35: SMS SFDC | C35: Master Data | D35: SMS - Asset | E35: Onity NA | G35: TRUE | H35: TRUE | I35: TRUE | J35: FALSE | K35: =REPT("|||||||||||||||||||||||",COUNTIF(G35:J35,TRUE)) -> ||||||||||||||||||||||||||||||||||||||||||||||||||||||||||||||||||||| | L35: =TEXT(COUNTIF(G35:J35,TRUE)/COLUMNS(G35:J35),"0%") -> 75% | M35: 45945 | N35: 698763 | O35: 698763 | P35: =IFERROR(O35/N35,0) -> 1 | Q35: =IFERROR(N35-O35,0) -> 0 | R35: =IFERROR(Q35/N35,0) -> 0 | S35: Pending Load (Awaiting Ship-To Data)
A36: 35 | B36: SMS SFDC | C36: Master Data | D36: SMS - Location | E36: Onity NA | G36: TRUE | H36: TRUE | I36: TRUE | J36: TRUE | K36: =REPT("|||||||||||||||||||||||",COUNTIF(G36:J36,TRUE)) -> |||||||||||||||||||||||||||||||||||||||||||||||||||||||||||||||||||||||||||||||||||||||||||| | L36: =TEXT(COUNTIF(G36:J36,TRUE)/COLUMNS(G36:J36),"0%") -> 100% | M36: 45939 | N36: 12070 | O36: 12070 | P36: =IFERROR(O36/N36,0) -> 1 | Q36: =IFERROR(N36-O36,0) -> 0 | R36: =IFERROR(Q36/N36,0) -> 0 | S36: Sudhanshu to load this from ERP
A37: 36 | B37: SMS SFDC | C37: Transactional Data | D37: Service Contract | E37: Onity EMEA | F37: Aberlardo / Sonia | G37: TRUE | H37: TRUE | I37: TRUE | J37: FALSE | K37: =REPT("|||||||||||||||||||||||",COUNTIF(G37:J37,TRUE)) -> ||||||||||||||||||||||||||||||||||||||||||||||||||||||||||||||||||||| | L37: =TEXT(COUNTIF(G37:J37,TRUE)/COLUMNS(G37:J37),"0%") -> 75% | M37: 45945 | N37: 289 | O37: 289 | P37: =IFERROR(O37/N37,0) -> 1 | Q37: 0 | R37: =IFERROR(Q37/N37,0) -> 0
A38: 37 | B38: SMS SFDC | C38: Master Data | D38: SMS - Service Resources (Subcontractors and internal) | E38: Onity EMEA | G38: TRUE | H38: TRUE | I38: TRUE | J38: FALSE | K38: =REPT("|||||||||||||||||||||||",COUNTIF(G38:J38,TRUE)) -> ||||||||||||||||||||||||||||||||||||||||||||||||||||||||||||||||||||| | L38: =TEXT(COUNTIF(G38:J38,TRUE)/COLUMNS(G38:J38),"0%") -> 75% | M38: 45945 | N38: 14 | O38: 14 | P38: =IFERROR(O38/N38,0) -> 1 | Q38: 0 | R38: =IFERROR(Q38/N38,0) -> 0
A39: 38 | B39: SMS SFDC | C39: Master Data | D39: SMS - Work Type Setup | E39: Onity EMEA | G39: TRUE | H39: TRUE | I39: TRUE | J39: FALSE | K39: =REPT("|||||||||||||||||||||||",COUNTIF(G39:J39,TRUE)) -> ||||||||||||||||||||||||||||||||||||||||||||||||||||||||||||||||||||| | L39: =TEXT(COUNTIF(G39:J39,TRUE)/COLUMNS(G39:J39),"0%") -> 75% | M39: 45945 | N39: 48 | O39: 48 | P39: =IFERROR(O39/N39,0) -> 1 | Q39: =IFERROR(N39-O39,0) -> 0 | R39: =IFERROR(Q39/N39,0) -> 0
A40: 39 | B40: SMS SFDC | C40: Master Data | D40: SMS - Service Territory | E40: Onity EMEA | G40: TRUE | H40: TRUE | I40: TRUE | J40: TRUE | K40: =REPT("|||||||||||||||||||||||",COUNTIF(G40:J40,TRUE)) -> |||||||||||||||||||||||||||||||||||||||||||||||||||||||||||||||||||||||||||||||||||||||||||| | L40: =TEXT(COUNTIF(G40:J40,TRUE)/COLUMNS(G40:J40),"0%") -> 100% | M40: 45945 | N40: 3 | O40: 3 | P40: =IFERROR(O40/N40,0) -> 1 | Q40: =IFERROR(N40-O40,0) -> 0 | R40: =IFERROR(Q40/N40,0) -> 0
...

Sheet CCEX Data Score Card - Prod
A1: S.No | B1: System | C1: Data Object Type | D1: Data Object | E1: Region | F1: Business Focal | G1: Identify CDE | H1: Prep Data | I1: Load | J1: Validation | K1: Status % | L1: Progress | M1: ETA for Load | N1: Expected Records (PROD) | O1: Loaded Records (PROD) | P1: % Loaded (PROD) | Q1: Missed Records (PROD) | R1: % Problem (PROD | S1: Remarks / Comments during PROD
A2: 1 | B2: Salesforce | C2: Master Data | D2: Account (Buying) | E2: Onity NA | F2: Brian Bevins - Sales, Anne Kelly - CS Chris Taylor - TC | G2: TRUE | H2: TRUE | I2: TRUE | J2: TRUE | K2: =REPT("|||||||||||||||||||||||",COUNTIF(G2:J2,TRUE)) -> |||||||||||||||||||||||||||||||||||||||||||||||||||||||||||||||||||||||||||||||||||||||||||| | L2: =TEXT(COUNTIF(G2:J2,TRUE)/COLUMNS(G2:J2),"0%") -> 100% | M2: 45938 | N2: 36574 | O2: 36574 | P2: =IFERROR(O2/N2,0) -> 1 | Q2: =N2-(IF(ISBLANK(O2),N2,O2)) -> 0 | R2: =IFERROR(Q2/N2,0) -> 0
A3: 2 | B3: Salesforce | C3: Master Data | D3: Account (Non-Buying) | E3: Onity NA | G3: TRUE | H3: TRUE | I3: TRUE | J3: TRUE | K3: =REPT("|||||||||||||||||||||||",COUNTIF(G3:J3,TRUE)) -> |||||||||||||||||||||||||||||||||||||||||||||||||||||||||||||||||||||||||||||||||||||||||||| | L3: =TEXT(COUNTIF(G3:J3,TRUE)/COLUMNS(G3:J3),"0%") -> 100% | M3: 45954 | N3: 112614 | O3: 112614 | P3: =IFERROR(O3/N3,0) -> 1 | Q3: =N3-(IF(ISBLANK(O3),N3,O3)) -> 0 | R3: =IFERROR(Q3/N3,0) -> 0
A4: 3 | B4: Salesforce | C4: Master Data | D4: Contact | E4: Onity NA | G4: TRUE | H4: TRUE | I4: TRUE | J4: TRUE | K4: =REPT("|||||||||||||||||||||||",COUNTIF(G4:J4,TRUE)) -> |||||||||||||||||||||||||||||||||||||||||||||||||||||||||||||||||||||||||||||||||||||||||||| | L4: =TEXT(COUNTIF(G4:J4,TRUE)/COLUMNS(G4:J4),"0%") -> 100% | M4: 45958 | N4: 153580 | O4: 153580 | P4: =IFERROR(O4/N4,0) -> 1 | Q4: =N4-(IF(ISBLANK(O4),N4,O4)) -> 0 | R4: =IFERROR(Q4/N4,0) -> 0 | S4: 40727 (duplicate)
A5: 4 | B5: Salesforce | C5: Master Data | D5: Product | E5: Onity NA | G5: TRUE | H5: TRUE | I5: TRUE | J5: TRUE | K5: =REPT("|||||||||||||||||||||||",COUNTIF(G5:J5,TRUE)) -> |||||||||||||||||||||||||||||||||||||||||||||||||||||||||||||||||||||||||||||||||||||||||||| | L5: =TEXT(COUNTIF(G5:J5,TRUE)/COLUMNS(G5:J5),"0%") -> 100% | M5: 45938 | N5: 6094 | O5: 6094 | P5: =IFERROR(O5/N5,0) -> 1 | Q5: =N5-(IF(ISBLANK(O5),N5,O5)) -> 0 | R5: =IFERROR(Q5/N5,0) -> 0 | S5: 1 product and 4 prices are not correct with data validated.
A6: 5 | B6: Salesforce | C6: Transactional Data | D6: Opportunity | E6: Onity NA | G6: TRUE | H6: TRUE | I6: TRUE | J6: TRUE | K6: =REPT("|||||||||||||||||||||||",COUNTIF(G6:J6,TRUE)) -> |||||||||||||||||||||||||||||||||||||||||||||||||||||||||||||||||||||||||||||||||||||||||||| | L6: =TEXT(COUNTIF(G6:J6,TRUE)/COLUMNS(G6:J6),"0%") -> 100% | M6: 45963 | N6: 13665 | O6: 13665 | P6: =IFERROR(O6/N6,0) -> 1 | Q6: =N6-(IF(ISBLANK(O6),N6,O6)) -> 0 | R6: =IFERROR(Q6/N6,0) -> 0
A7: 6 | B7: Salesforce | C7: Transactional Data | D7: Lead | E7: Onity NA | G7: TRUE | H7: TRUE | I7: TRUE | J7: TRUE | K7: =REPT("|||||||||||||||||||||||",COUNTIF(G7:J7,TRUE)) -> |||||||||||||||||||||||||||||||||||||||||||||||||||||||||||||||||||||||||||||||||||||||||||| | L7: =TEXT(COUNTIF(G7:J7,TRUE)/COLUMNS(G7:J7),"0%") -> 100% | M7: 45962 | N7: 352 | O7: 352 | P7: =IFERROR(O7/N7,0) -> 1 | Q7: =N7-(IF(ISBLANK(O7),N7,O7)) -> 0 | R7: =IFERROR(Q7/N7,0) -> 0
A8: 7 | B8: Salesforce | C8: Transactional Data | D8: Contract | E8: Onity NA | G8: TRUE | H8: TRUE | I8: TRUE | J8: TRUE | K8: =REPT("|||||||||||||||||||||||",COUNTIF(G8:J8,TRUE)) -> |||||||||||||||||||||||||||||||||||||||||||||||||||||||||||||||||||||||||||||||||||||||||||| | L8: =TEXT(COUNTIF(G8:J8,TRUE)/COLUMNS(G8:J8),"0%") -> 100% | M8: 45969 | N8: 5904 | O8: 5836 | P8: =IFERROR(O8/N8,0) -> 0.98848238 | Q8: =N8-(IF(ISBLANK(O8),N8,O8)) -> 68 | R8: =IFERROR(Q8/N8,0) -> 0.011517615
A9: 8 | B9: Salesforce | C9: Transactional Data | D9: Case | E9: Onity NA | G9: TRUE | H9: TRUE | I9: TRUE | J9: TRUE | K9: =REPT("|||||||||||||||||||||||",COUNTIF(G9:J9,TRUE)) -> |||||||||||||||||||||||||||||||||||||||||||||||||||||||||||||||||||||||||||||||||||||||||||| | L9: =TEXT(COUNTIF(G9:J9,TRUE)/COLUMNS(G9:J9),"0%") -> 100% | M9: 45962 | N9: 100979 | O9: 100979 | P9: =IFERROR(O9/N9,0) -> 1 | Q9: =N9-(IF(ISBLANK(O9),N9,O9)) -> 0 | R9: =IFERROR(Q9/N9,0) -> 0 | S9: child cases getting created.
A10: 9 | B10: Salesforce | C10: Transactional Data | D10: Knowledge Articles | E10: Onity NA | G10: TRUE | H10: TRUE | I10: TRUE | J10: TRUE | K10: =REPT("|||||||||||||||||||||||",COUNTIF(G10:J10,TRUE)) -> |||||||||||||||||||||||||||||||||||||||||||||||||||||||||||||||||||||||||||||||||||||||||||| | L10: =TEXT(COUNTIF(G10:J10,TRUE)/COLUMNS(G10:J10),"0%") -> 100% | M10: 45964 | N10: 345 | O10: 345 | P10: =IFERROR(O10/N10,0) -> 1 | Q10: =N10-(IF(ISBLANK(O10),N10,O10)) -> 0 | R10: =IFERROR(Q10/N10,0) -> 0 | S10: Don't have the catagories brought over from BTFull and that they were all still in draft form becuase the pictures / attachments hadnt migrated over yet.
A11: 10 | B11: Salesforce | C11: Master Data | D11: Account (Buying) | E11: Onity EMEA | F11: Piorno Abelardo Sonia Estrada | G11: TRUE | H11: TRUE | I11: TRUE | J11: TRUE | K11: =REPT("|||||||||||||||||||||||",COUNTIF(G11:J11,TRUE)) -> |||||||||||||||||||||||||||||||||||||||||||||||||||||||||||||||||||||||||||||||||||||||||||| | L11: =TEXT(COUNTIF(G11:J11,TRUE)/COLUMNS(G11:J11),"0%") -> 100% | M11: 45938 | N11: 17078 | O11: 17078 | P11: =IFERROR(O11/N11,0) -> 1 | Q11: =N11-(IF(ISBLANK(O11),N11,O11)) -> 0 | R11: =IFERROR(Q11/N11,0) -> 0
A12: 11 | B12: Salesforce | C12: Master Data | D12: Account (Non-Buying) | E12: Onity EMEA | G12: TRUE | H12: TRUE | I12: TRUE | J12: TRUE | K12: =REPT("|||||||||||||||||||||||",COUNTIF(G12:J12,TRUE)) -> |||||||||||||||||||||||||||||||||||||||||||||||||||||||||||||||||||||||||||||||||||||||||||| | L12: =TEXT(COUNTIF(G12:J12,TRUE)/COLUMNS(G12:J12),"0%") -> 100% | M12: 45953 | N12: 12621 | O12: 12621 | P12: =IFERROR(O12/N12,0) -> 1 | Q12: =N12-(IF(ISBLANK(O12),N12,O12)) -> 0 | R12: =IFERROR(Q12/N12,0) -> 0
A13: 12 | B13: Salesforce | C13: Master Data | D13: Contact | E13: Onity EMEA | G13: TRUE | H13: TRUE | I13: TRUE | J13: TRUE | K13: =REPT("|||||||||||||||||||||||",COUNTIF(G13:J13,TRUE)) -> |||||||||||||||||||||||||||||||||||||||||||||||||||||||||||||||||||||||||||||||||||||||||||| | L13: =TEXT(COUNTIF(G13:J13,TRUE)/COLUMNS(G13:J13),"0%") -> 100% | M13: 45958 | N13: 21914 | O13: 21914 | P13: =IFERROR(O13/N13,0) -> 1 | Q13: =N13-(IF(ISBLANK(O13),N13,O13)) -> 0 | R13: =IFERROR(Q13/N13,0) -> 0 | S13: 855 (Duplicate)
A14: 13 | B14: Salesforce | C14: Master Data | D14: Product | E14: Onity EMEA | G14: TRUE | H14: TRUE | I14: TRUE | J14: TRUE | K14: =REPT("|||||||||||||||||||||||",COUNTIF(G14:J14,TRUE)) -> |||||||||||||||||||||||||||||||||||||||||||||||||||||||||||||||||||||||||||||||||||||||||||| | L14: =TEXT(COUNTIF(G14:J14,TRUE)/COLUMNS(G14:J14),"0%") -> 100% | M14: 45938 | N14: 18718 | O14: 18718 | P14: =IFERROR(O14/N14,0) -> 1 | Q14: =N14-(IF(ISBLANK(O14),N14,O14)) -> 0 | R14: =IFERROR(Q14/N14,0) -> 0
A15: 14 | B15: Salesforce | C15: Transactional Data | D15: Opportunity | E15: Onity EMEA | G15: TRUE | H15: TRUE | I15: TRUE | J15: TRUE | K15: =REPT("|||||||||||||||||||||||",COUNTIF(G15:J15,TRUE)) -> |||||||||||||||||||||||||||||||||||||||||||||||||||||||||||||||||||||||||||||||||||||||||||| | L15: =TEXT(COUNTIF(G15:J15,TRUE)/COLUMNS(G15:J15),"0%") -> 100% | M15: 45962 | N15: 32144 | O15: 32144 | P15: =IFERROR(O15/N15,0) -> 1 | Q15: =N15-(IF(ISBLANK(O15),N15,O15)) -> 0 | R15: =IFERROR(Q15/N15,0) -> 0
A16: 15 | B16: Salesforce | C16: Transactional Data | D16: Case | E16: Onity EMEA | G16: TRUE | H16: TRUE | I16: TRUE | J16: TRUE | K16: =REPT("|||||||||||||||||||||||",COUNTIF(G16:J16,TRUE)) -> |||||||||||||||||||||||||||||||||||||||||||||||||||||||||||||||||||||||||||||||||||||||||||| | L16: =TEXT(COUNTIF(G16:J16,TRUE)/COLUMNS(G16:J16),"0%") -> 100% | M16: 45963 | N16: 2134 | O16: 2134 | P16: =IFERROR(O16/N16,0) -> 1 | Q16: =N16-(IF(ISBLANK(O16),N16,O16)) -> 0 | R16: =IFERROR(Q16/N16,0) -> 0
A17: 16 | B17: Salesforce | C17: Transactional Data | D17: Quote | E17: Onity EMEA | G17: TRUE | H17: TRUE | I17: TRUE | J17: TRUE | K17: =REPT("|||||||||||||||||||||||",COUNTIF(G17:J17,TRUE)) -> |||||||||||||||||||||||||||||||||||||||||||||||||||||||||||||||||||||||||||||||||||||||||||| | L17: =TEXT(COUNTIF(G17:J17,TRUE)/COLUMNS(G17:J17),"0%") -> 100% | M17: 45968 | N17: 8508 | O17: 8508 | P17: =IFERROR(O17/N17,0) -> 1 | Q17: =N17-(IF(ISBLANK(O17),N17,O17)) -> 0 | R17: =IFERROR(Q17/N17,0) -> 0
A18: 17 | B18: Salesforce | C18: Master Data | D18: Account (Buying) | E18: Onity APAC | F18: Chin Edmond- RoA Suriati Nur- GC, RoA David Carran- Ken Ong - ANZ James Eapen- Ind | G18: TRUE | H18: TRUE | I18: TRUE | J18: TRUE | K18: =REPT("|||||||||||||||||||||||",COUNTIF(G18:J18,TRUE)) -> |||||||||||||||||||||||||||||||||||||||||||||||||||||||||||||||||||||||||||||||||||||||||||| | L18: =TEXT(COUNTIF(G18:J18,TRUE)/COLUMNS(G18:J18),"0%") -> 100% | M18: 45938 | N18: 1061 | O18: 1061 | P18: =IFERROR(O18/N18,0) -> 1 | Q18: =N18-(IF(ISBLANK(O18),N18,O18)) -> 0 | R18: =IFERROR(Q18/N18,0) -> 0
A19: 18 | B19: Salesforce | C19: Master Data | D19: Contact | E19: Onity APAC | G19: TRUE | H19: TRUE | I19: TRUE | J19: TRUE | K19: =REPT("|||||||||||||||||||||||",COUNTIF(G19:J19,TRUE)) -> |||||||||||||||||||||||||||||||||||||||||||||||||||||||||||||||||||||||||||||||||||||||||||| | L19: =TEXT(COUNTIF(G19:J19,TRUE)/COLUMNS(G19:J19),"0%") -> 100% | M19: 45955 | N19: 25 | O19: 25 | P19: =IFERROR(O19/N19,0) -> 1 | Q19: =N19-(IF(ISBLANK(O19),N19,O19)) -> 0 | R19: =IFERROR(Q19/N19,0) -> 0
A20: 19 | B20: Salesforce | C20: Master Data | D20: Product | E20: Onity APAC | G20: TRUE | H20: TRUE | I20: TRUE | J20: TRUE | K20: =REPT("|||||||||||||||||||||||",COUNTIF(G20:J20,TRUE)) -> |||||||||||||||||||||||||||||||||||||||||||||||||||||||||||||||||||||||||||||||||||||||||||| | L20: =TEXT(COUNTIF(G20:J20,TRUE)/COLUMNS(G20:J20),"0%") -> 100% | M20: 45938 | N20: 23291 | O20: 23291 | P20: =IFERROR(O20/N20,0) -> 1 | Q20: =N20-(IF(ISBLANK(O20),N20,O20)) -> 0 | R20: =IFERROR(Q20/N20,0) -> 0
A21: 20 | B21: Salesforce | C21: Master Data | D21: Account (Buying) | E21: Lenel APAC | F21: Suriati Nur- RoA, GC Ken Ong - ANZ James Eapen- Ind | G21: TRUE | H21: TRUE | I21: TRUE | J21: TRUE | K21: =REPT("|||||||||||||||||||||||",COUNTIF(G21:J21,TRUE)) -> |||||||||||||||||||||||||||||||||||||||||||||||||||||||||||||||||||||||||||||||||||||||||||| | L21: =TEXT(COUNTIF(G21:J21,TRUE)/COLUMNS(G21:J21),"0%") -> 100% | M21: 45938 | N21: 144 | O21: 144 | P21: =IFERROR(O21/N21,0) -> 1 | Q21: =N21-(IF(ISBLANK(O21),N21,O21)) -> 0 | R21: =IFERROR(Q21/N21,0) -> 0
A22: 21 | B22: Salesforce | C22: Master Data | D22: Account (Non-Buying) | E22: Lenel APAC | G22: TRUE | H22: TRUE | I22: TRUE | J22: TRUE | K22: =REPT("|||||||||||||||||||||||",COUNTIF(G22:J22,TRUE)) -> |||||||||||||||||||||||||||||||||||||||||||||||||||||||||||||||||||||||||||||||||||||||||||| | L22: =TEXT(COUNTIF(G22:J22,TRUE)/COLUMNS(G22:J22),"0%") -> 100% | M22: 45938 | N22: 9832 | O22: 9832 | P22: =IFERROR(O22/N22,0) -> 1 | Q22: =N22-(IF(ISBLANK(O22),N22,O22)) -> 0 | R22: =IFERROR(Q22/N22,0) -> 0
A23: 22 | B23: Salesforce | C23: Master Data | D23: Contact | E23: Lenel APAC | G23: TRUE | H23: TRUE | I23: TRUE | J23: TRUE | K23: =REPT("|||||||||||||||||||||||",COUNTIF(G23:J23,TRUE)) -> |||||||||||||||||||||||||||||||||||||||||||||||||||||||||||||||||||||||||||||||||||||||||||| | L23: =TEXT(COUNTIF(G23:J23,TRUE)/COLUMNS(G23:J23),"0%") -> 100% | M23: 45938 | N23: 4936 | O23: 4936 | P23: =IFERROR(O23/N23,0) -> 1 | Q23: =N23-(IF(ISBLANK(O23),N23,O23)) -> 0 | R23: =IFERROR(Q23/N23,0) -> 0
A24: 23 | B24: Salesforce | C24: Master Data | D24: Product | E24: Lenel APAC | G24: TRUE | H24: TRUE | I24: TRUE | J24: TRUE | K24: =REPT("|||||||||||||||||||||||",COUNTIF(G24:J24,TRUE)) -> |||||||||||||||||||||||||||||||||||||||||||||||||||||||||||||||||||||||||||||||||||||||||||| | L24: =TEXT(COUNTIF(G24:J24,TRUE)/COLUMNS(G24:J24),"0%") -> 100% | M24: 45938 | N24: 3736 | O24: 3736 | P24: =IFERROR(O24/N24,0) -> 1 | Q24: =N24-(IF(ISBLANK(O24),N24,O24)) -> 0 | R24: =IFERROR(Q24/N24,0) -> 0
A25: 24 | B25: Salesforce | C25: Transactional Data | D25: Opportunity | E25: Lenel APAC | G25: TRUE | H25: TRUE | I25: TRUE | J25: TRUE | K25: =REPT("|||||||||||||||||||||||",COUNTIF(G25:J25,TRUE)) -> |||||||||||||||||||||||||||||||||||||||||||||||||||||||||||||||||||||||||||||||||||||||||||| | L25: =TEXT(COUNTIF(G25:J25,TRUE)/COLUMNS(G25:J25),"0%") -> 100% | M25: 45938 | N25: 1168 | O25: 1168 | P25: =IFERROR(O25/N25,0) -> 1 | Q25: =N25-(IF(ISBLANK(O25),N25,O25)) -> 0 | R25: =IFERROR(Q25/N25,0) -> 0
A26: 25 | B26: SMS SFDC | C26: Transactional Data | D26: SMS -Service Contract | E26: Lenel APAC | G26: TRUE | H26: TRUE | I26: TRUE | J26: TRUE | K26: =REPT("|||||||||||||||||||||||",COUNTIF(G26:J26,TRUE)) -> |||||||||||||||||||||||||||||||||||||||||||||||||||||||||||||||||||||||||||||||||||||||||||| | L26: =TEXT(COUNTIF(G26:J26,TRUE)/COLUMNS(G26:J26),"0%") -> 100% | M26: 45938 | N26: 34 | O26: 34 | P26: =IFERROR(O26/N26,0) -> 1 | Q26: =N26-(IF(ISBLANK(O26),N26,O26)) -> 0 | R26: =IFERROR(Q26/N26,0) -> 0
A27: 26 | B27: SMS SFDC | C27: Master Data | D27: SMS - Service Resources (Subcontractors and internal) | E27: Onity NA | F27: Kathleen / Marianne | G27: TRUE | H27: TRUE | I27: TRUE | J27: TRUE | K27: =REPT("|||||||||||||||||||||||",COUNTIF(G27:J27,TRUE)) -> |||||||||||||||||||||||||||||||||||||||||||||||||||||||||||||||||||||||||||||||||||||||||||| | L27: =TEXT(COUNTIF(G27:J27,TRUE)/COLUMNS(G27:J27),"0%") -> 100% | M27: 45959 | N27: 44 | O27: 44 | P27: =IFERROR(O27/N27,0) -> 1 | Q27: =N27-(IF(ISBLANK(O27),N27,O27)) -> 0 | R27: =IFERROR(Q27/N27,0) -> 0
A28: 27 | B28: SMS SFDC | C28: Master Data | D28: SMS - Work Type Setup | E28: Onity NA | G28: TRUE | H28: TRUE | I28: TRUE | J28: TRUE | K28: =REPT("|||||||||||||||||||||||",COUNTIF(G28:J28,TRUE)) -> |||||||||||||||||||||||||||||||||||||||||||||||||||||||||||||||||||||||||||||||||||||||||||| | L28: =TEXT(COUNTIF(G28:J28,TRUE)/COLUMNS(G28:J28),"0%") -> 100% | M28: 45954 | N28: 124 | O28: 124 | P28: =IFERROR(O28/N28,0) -> 1 | Q28: =N28-(IF(ISBLANK(O28),N28,O28)) -> 0 | R28: =IFERROR(Q28/N28,0) -> 0
A29: 28 | B29: SMS SFDC | C29: Transactional Data | D29: SMS -Service Contract | E29: Onity NA | G29: TRUE | H29: TRUE | I29: TRUE | J29: TRUE | K29: =REPT("|||||||||||||||||||||||",COUNTIF(G29:J29,TRUE)) -> |||||||||||||||||||||||||||||||||||||||||||||||||||||||||||||||||||||||||||||||||||||||||||| | L29: =TEXT(COUNTIF(G29:J29,TRUE)/COLUMNS(G29:J29),"0%") -> 100% | M29: 45968 | N29: 3513 | O29: 3513 | P29: =IFERROR(O29/N29,0) -> 1 | Q29: =N29-(IF(ISBLANK(O29),N29,O29)) -> 0 | R29: =IFERROR(Q29/N29,0) -> 0 | S29: Missing extended warranty/service contracts on some accounts, especially those created after initial ERP load.
A30: 29 | B30: SMS SFDC | C30: Master Data | D30: SMS - Service Territory | E30: Onity NA | G30: TRUE | H30: TRUE | I30: TRUE | J30: TRUE | K30: =REPT("|||||||||||||||||||||||",COUNTIF(G30:J30,TRUE)) -> |||||||||||||||||||||||||||||||||||||||||||||||||||||||||||||||||||||||||||||||||||||||||||| | L30: =TEXT(COUNTIF(G30:J30,TRUE)/COLUMNS(G30:J30),"0%") -> 100% | M30: 45951 | N30: 4 | O30: 4 | P30: =IFERROR(O30/N30,0) -> 1 | Q30: =N30-(IF(ISBLANK(O30),N30,O30)) -> 0 | R30: =IFERROR(Q30/N30,0) -> 0
A31: 30 | B31: SMS SFDC | C31: Master Data | D31: SMS - Profit Center | E31: Onity NA | G31: TRUE | H31: TRUE | I31: TRUE | J31: TRUE | K31: =REPT("|||||||||||||||||||||||",COUNTIF(G31:J31,TRUE)) -> |||||||||||||||||||||||||||||||||||||||||||||||||||||||||||||||||||||||||||||||||||||||||||| | L31: =TEXT(COUNTIF(G31:J31,TRUE)/COLUMNS(G31:J31),"0%") -> 100% | M31: 45952 | N31: 8 | O31: 8 | P31: =IFERROR(O31/N31,0) -> 1 | Q31: =N31-(IF(ISBLANK(O31),N31,O31)) -> 0 | R31: =IFERROR(Q31/N31,0) -> 0
A32: 31 | B32: SMS SFDC | C32: Master Data | D32: SMS - Service Resource Setup | E32: Onity NA | G32: TRUE | H32: TRUE | I32: TRUE | J32: TRUE | K32: =REPT("|||||||||||||||||||||||",COUNTIF(G32:J32,TRUE)) -> |||||||||||||||||||||||||||||||||||||||||||||||||||||||||||||||||||||||||||||||||||||||||||| | L32: =TEXT(COUNTIF(G32:J32,TRUE)/COLUMNS(G32:J32),"0%") -> 100% | M32: 45960 | N32: 122 | O32: 122 | P32: =IFERROR(O32/N32,0) -> 1 | Q32: =N32-(IF(ISBLANK(O32),N32,O32)) -> 0 | R32: =IFERROR(Q32/N32,0) -> 0
A33: 32 | B33: SMS SFDC | C33: Master Data | D33: SMS - Asset | E33: Onity NA | G33: TRUE | H33: TRUE | I33: TRUE | J33: TRUE | K33: =REPT("|||||||||||||||||||||||",COUNTIF(G33:J33,TRUE)) -> |||||||||||||||||||||||||||||||||||||||||||||||||||||||||||||||||||||||||||||||||||||||||||| | L33: =TEXT(COUNTIF(G33:J33,TRUE)/COLUMNS(G33:J33),"0%") -> 100% | M33: 45968 | N33: 683000 | O33: 557149 | P33: =IFERROR(O33/N33,0) -> 0.81573792 | Q33: =N33-(IF(ISBLANK(O33),N33,O33)) -> 125851 | R33: =IFERROR(Q33/N33,0) -> 0.18426208 | S33: Nitesh will share the record count (expected and loaded)
A34: 33 | B34: SMS SFDC | C34: Master Data | D34: SMS - Location | E34: Onity NA | G34: TRUE | H34: TRUE | I34: TRUE | J34: TRUE | K34: =REPT("|||||||||||||||||||||||",COUNTIF(G34:J34,TRUE)) -> |||||||||||||||||||||||||||||||||||||||||||||||||||||||||||||||||||||||||||||||||||||||||||| | L34: =TEXT(COUNTIF(G34:J34,TRUE)/COLUMNS(G34:J34),"0%") -> 100% | M34: 45951 | N34: 12070 | O34: 12070 | P34: =IFERROR(O34/N34,0) -> 1 | Q34: =N34-(IF(ISBLANK(O34),N34,O34)) -> 0 | R34: =IFERROR(Q34/N34,0) -> 0
A35: 34 | B35: SMS SFDC | C35: Master Data | D35: SMS - Service Resources (Subcontractors and internal) | E35: Onity EMEA | G35: TRUE | H35: TRUE | I35: TRUE | J35: TRUE | K35: =REPT("|||||||||||||||||||||||",COUNTIF(G35:J35,TRUE)) -> |||||||||||||||||||||||||||||||||||||||||||||||||||||||||||||||||||||||||||||||||||||||||||| | L35: =TEXT(COUNTIF(G35:J35,TRUE)/COLUMNS(G35:J35),"0%") -> 100% | M35: 45959 | N35: 25 | O35: 25 | P35: =IFERROR(O35/N35,0) -> 1 | Q35: =N35-(IF(ISBLANK(O35),N35,O35)) -> 0 | R35: =IFERROR(Q35/N35,0) -> 0
A36: 35 | B36: SMS SFDC | C36: Master Data | D36: SMS - Work Type Setup | E36: Onity EMEA | G36: TRUE | H36: TRUE | I36: TRUE | J36: TRUE | K36: =REPT("|||||||||||||||||||||||",COUNTIF(G36:J36,TRUE)) -> |||||||||||||||||||||||||||||||||||||||||||||||||||||||||||||||||||||||||||||||||||||||||||| | L36: =TEXT(COUNTIF(G36:J36,TRUE)/COLUMNS(G36:J36),"0%") -> 100% | M36: 45954 | N36: 124 | O36: 124 | P36: =IFERROR(O36/N36,0) -> 1 | Q36: =N36-(IF(ISBLANK(O36),N36,O36)) -> 0 | R36: =IFERROR(Q36/N36,0) -> 0
A37: 36 | B37: SMS SFDC | C37: Master Data | D37: SMS - Service Territory | E37: Onity EMEA | G37: TRUE | H37: TRUE | I37: TRUE | J37: TRUE | K37: =REPT("|||||||||||||||||||||||",COUNTIF(G37:J37,TRUE)) -> |||||||||||||||||||||||||||||||||||||||||||||||||||||||||||||||||||||||||||||||||||||||||||| | L37: =TEXT(COUNTIF(G37:J37,TRUE)/COLUMNS(G37:J37),"0%") -> 100% | M37: 45951 | N37: 3 | O37: 3 | P37: =IFERROR(O37/N37,0) -> 1 | Q37: =N37-(IF(ISBLANK(O37),N37,O37)) -> 0 | R37: =IFERROR(Q37/N37,0) -> 0
A38: 37 | B38: SMS SFDC | C38: Transactional Data | D38: SMS -Service Contract | E38: Onity EMEA | G38: TRUE | H38: TRUE | I38: TRUE | J38: TRUE | K38: =REPT("|||||||||||||||||||||||",COUNTIF(G38:J38,TRUE)) -> |||||||||||||||||||||||||||||||||||||||||||||||||||||||||||||||||||||||||||||||||||||||||||| | L38: =TEXT(COUNTIF(G38:J38,TRUE)/COLUMNS(G38:J38),"0%") -> 100% | M38: 45968 | N38: 247 | O38: 247 | P38: =IFERROR(O38/N38,0) -> 1 | Q38: =N38-(IF(ISBLANK(O38),N38,O38)) -> 0 | R38: =IFERROR(Q38/N38,0) -> 0
A39: 38 | B39: SMS SFDC | C39: Master Data | D39: SMS - Profit Center | E39: Onity EMEA | G39: TRUE | H39: TRUE | I39: TRUE | J39: TRUE | K39: =REPT("|||||||||||||||||||||||",COUNTIF(G39:J39,TRUE)) -> |||||||||||||||||||||||||||||||||||||||||||||||||||||||||||||||||||||||||||||||||||||||||||| | L39: =TEXT(COUNTIF(G39:J39,TRUE)/COLUMNS(G39:J39),"0%") -> 100% | M39: 45952 | N39: 8 | O39: 8 | P39: =IFERROR(O39/N39,0) -> 1 | Q39: =N39-(IF(ISBLANK(O39),N39,O39)) -> 0 | R39: =IFERROR(Q39/N39,0) -> 0
A40: 39 | B40: SMS SFDC | C40: Master Data | D40: SMS - Service Resource Setup | E40: Onity EMEA | G40: TRUE | H40: TRUE | I40: TRUE | J40: TRUE | K40: =REPT("|||||||||||||||||||||||",COUNTIF(G40:J40,TRUE)) -> |||||||||||||||||||||||||||||||||||||||||||||||||||||||||||||||||||||||||||||||||||||||||||| | L40: =TEXT(COUNTIF(G40:J40,TRUE)/COLUMNS(G40:J40),"0%") -> 100% | M40: 45960 | N40: 67 | O40: 67 | P40: =IFERROR(O40/N40,0) -> 1 | Q40: =N40-(IF(ISBLANK(O40),N40,O40)) -> 0 | R40: =IFERROR(Q40/N40,0) -> 0
...

Sheet Dashboard_Data Upload Count
A1: # | B1: Key Data Objects | C1: Source | D1: Target | E1: Master Data / Transactional Data | F1: Ent. IT Focal (Migration) | G1: BA IT Focal (Validation) | H1: Business Focal Name (Validation) Onity NA | I1: Business Focal Name (Validation) Onity EMEA | J1: Business Focal Name (Validation) Onity APAC | K1: Business Focal Name (Validation) Lenel APAC | L1: Production Load Progress | M1: Data Extract, upload Link path | N1: Expected Records in PROD Onity NA | O1: Expected Records in PROD Onity EMEA | P1: Expected Records in PROD Onity APAC | Q1: Expected Records in PROD Lenel APAC | R1: Loaded Records in PROD Onity NA | S1: Loaded Records in PROD Onity EMEA | T1: Loaded Records in PROD Onity APAC | U1: Loaded Records in PROD Lenel APAC | V1: % Loaded | W1: % Problem | X1: Remarks
A2: 1 | B2: Contacts | C2: GDM SFDC | D2: Contact Center | E2: Master Data | F2: Nagendra | G2: Chris Taylor Czerwinski, Ron | H2: Anne Kelly | I2: NA | J2: NA | K2: NA | L2: Not Started | N2: 124402 | O2: NA | P2: NA | Q2: NA | R2: 124402 | S2: NA | T2: NA | U2: NA
A3: 2 | B3: Material | C3: ERP | D3: CPQ | E3: Master Data | F3: Ashutosh Mishra | G3: Amit / Ambresh | H3: Shedd, Nicole Bevins, Brian | I3: Piorno, Abelardo | J3: Aggarwal, Dhruv Ganta, Manoj Kumar | K3: Aggarwal, Dhruv Ganta, Manoj Kumar | L3: Not Started | N3: 5450 | O3: 5969 | Q3: 5000 | R3: 5450 | S3: 5969
A4: 3 | B4: Price | C4: ERP | D4: CPQ | E4: Master Data | G4: Amit / Ambresh | L4: Not Started | N4: 5450 | O4: 5969 | Q4: 5000 | R4: 5450 | S4: 5969
A5: 4 | B5: Region Mapping (CT_OGC_REGION_MAPPING) | C5: Business/ Manual | D5: CPQ | E5: Master Data | G5: Amit / Ambresh | L5: Not Started
A6: 5 | B6: Contract (CT_AS_CONTRACT_ZA_ZL) | C6: Business/ Manual | D6: CPQ | E6: Master Data | G6: Amit / Ambresh | L6: Not Started
A7: 6 | B7: Material | C7: ERP / EPIM | D7: E-Commerce | E7: Master Data | F7: Sunny Pachnanda | G7: Saquib Imam | H7: Anne Kelly | I7: NA | J7: NA | K7: NA | L7: Not Started | N7: 18 | O7: NA | P7: NA | Q7: NA | S7: NA | T7: NA | U7: NA
A8: 7 | B8: Accounts (Buying) | C8: ERP | D8: E-Commerce | E8: Master Data | F8: Saquib Imam | G8: Saquib Imam | L8: Not Started | N8: 18 | O8: NA | P8: NA | Q8: NA | S8: NA | T8: NA | U8: NA
A9: 8 | B9: Credit Card MID | C9: NA | D9: E-Commerce | E9: Master Data | L9: Not Started | N9: 18
A10: 9 | B10: Price | C10: ERP | D10: E-Commerce | E10: Master Data | F10: Saquib Imam | G10: Saquib Imam | L10: Not Started | N10: 18 | O10: NA | P10: NA | Q10: NA | S10: NA | T10: NA | U10: NA
A11: 10 | B11: Leads | C11: HubSpot | D11: GDM Marketo | E11: Transactional Data | F11: Rawat Devendra Singh | G11: Amandeep | H11: Kendall Simich | I11: Kendall Simich | J11: NA | K11: NA | L11: Not Started
A12: 11 | B12: Accounts (Buying) | C12: Source SFDC | D12: GDM SFDC | E12: Master Data | F12: Yaswanth\Divya | G12: Amit / Ambresh | H12: Brain Bevins - Sales Kelly Anne - CS Chris Taylor - TC | I12: Piorno Abelardo Sonia Estrada | J12: Chin Edmond- RoA Suriati Nur- GC, RoA David Carran- Ken Ong - ANZ James Eapen- Ind | K12: Suriati Nur- RoA, GC Ken Ong - ANZ James Eapen- Ind | L12: Not Started | N12: 6603 | O12: 8281 | P12: 26 | Q12: 1160 | R12: 6603 | S12: 8281 | T12: 26 | U12: 1160
A13: 12 | B13: Accounts (Non-Buying) | C13: Source SFDC | D13: GDM SFDC | E13: Master Data | G13: Amit / Ambresh | L13: Not Started | N13: 113845 | O13: 25901 | P13: NA | Q13: 9832 | R13: 113039 | S13: 25901 | T13: NA | U13: 9832
A14: 13 | B14: Source systems | C14: Source SFDC | D14: GDM SFDC | E14: Master Data | G14: Amit / Ambresh | L14: Not Started | N14: 19884 | O14: 29328 | P14: 13741 | Q14: 13741 | R14: 19884 | S14: 29328 | T14: 13741 | U14: 13741
